<?xml version="1.0" ?>
<!-- =================================================================================== -->
<!-- |    This document was autogenerated by xacro from /home/filippos/ros_ws/src/exp_excavator/urdf/PC1i.xacro | -->
<!-- |    EDITING THIS FILE BY HAND IS NOT RECOMMENDED                                 | -->
<!-- =================================================================================== -->
<robot name="PC1i" xmlns:xacro="http://www.ros.org/wiki/xacro">
  <link name="Base-link"/>
  <link name="Boom-link"/>
  <link name="Arm-link"/>
  <link name="Sensor-link"/>
  <link name="Bucket-link"/>
  <joint name="Boom" type="revolute">
    <axis xyz="0 0 1"/>
    <origin rpy="0 0 0" xyz="1 1 0"/>
    <limit effort="30" velocity="100.0"/>
    <parent link="Base-link"/>
    <child link="Boom-link"/>
  </joint>
  <joint name="Arm" type="revolute">
    <axis xyz="0 0 1"/>
    <origin rpy="0 0 0" xyz="0.7125 0 0"/>
    <limit effort="30" velocity="100.0"/>
    <parent link="Boom-link"/>
    <child link="Arm-link"/>
  </joint>
  <joint name="Bucket" type="revolute">
    <axis xyz="0 0 1"/>
    <origin rpy="0 0 0" xyz="0.3656 0 0"/>
    <limit effort="30" velocity="100.0"/>
    <parent link="Arm-link"/>
    <child link="Sensor-link"/>
  </joint>
  <joint name="Sensor-Bucket" type="fixed">
    <origin rpy="0.5 0 0" xyz="0.1858 0 0"/>
    <parent link="Sensor-link"/>
    <child link="Bucket-link"/>
  </joint>
  -

</robot>

